<?xml version="1.0" ?>
<!-- with panda arm -->
<robot name="panda">
 <link name = "world" />
  <joint name="world_fixed" type="fixed">
    <origin xyz="0 0 0" rpy="0 0 0"/>
    <parent link="world"/>
    <child link="panda_link0"/>
  </joint>

    <link name="panda_link0">
        <visual>
            <geometry>
                <mesh filename="package://franka_panda_description/meshes/visual/link0.dae" />
            </geometry>
            <!-- <material name="panda_gray"/> -->
        </visual>
        <collision>
            <geometry>
                <mesh filename="package://franka_panda_description/meshes/collision/link0.stl" />
            </geometry>
        </collision>
        <inertial>
            <mass value="0.1" />
            <origin xyz="0 0 0" rpy="0 0 0" />
            <inertia ixx="0.03" iyy="0.03" izz="0.03" ixy="0.0" ixz="0.0" iyz="0.0" />
        </inertial>
    </link>
    <link name="panda_link1">
        <visual>
            <geometry>
                <mesh filename="package://franka_panda_description/meshes/visual/link1.dae" />
            </geometry>
        </visual>
        <collision>
            <geometry>
                <mesh filename="package://franka_panda_description/meshes/collision/link1.stl" />
            </geometry>
        </collision>
        <inertial>
            <origin rpy="0 0 0" xyz="3.875e-03 2.081e-03 -0.1750" />
            <mass value="4.970684" />
            <inertia ixx="7.0337e-01" ixy="-1.3900e-04" ixz="6.7720e-03" iyy="7.0661e-01" iyz="1.9169e-02" izz="9.1170e-03" />
        </inertial>
    </link>
    <joint name="panda_joint1" type="revolute">
        <safety_controller k_position="100.0" k_velocity="40.0" soft_lower_limit="-2.8973" soft_upper_limit="2.8973" />
        <origin rpy="0 0 0" xyz="0 0 0.333" />
        <parent link="panda_link0" />
        <child link="panda_link1" />
        <axis xyz="0 0 1" />
        <limit effort="87" lower="-2.8973" upper="2.8973" velocity="2.1750" />
        <dynamics damping="10.0" friction="5.0" />
    </joint>
    <link name="panda_link2">
        <visual>
            <geometry>
                <mesh filename="package://franka_panda_description/meshes/visual/link2.dae" />
            </geometry>
        </visual>
        <collision>
            <geometry>
                <mesh filename="package://franka_panda_description/meshes/collision/link2.stl" />
            </geometry>
        </collision>
        <inertial>
            <origin rpy="0 0 0" xyz="-3.141e-03 -2.872e-02 3.495e-03" />
            <mass value="0.646926" />
            <inertia ixx="7.9620e-03" ixy="-3.9250e-03" ixz="1.0254e-02" iyy="2.8110e-02" iyz="7.0400e-04" izz="2.5995e-02" />
        </inertial>
    </link>
    <joint name="panda_joint2" type="revolute">
        <safety_controller k_position="100.0" k_velocity="40.0" soft_lower_limit="-1.7628" soft_upper_limit="1.7628" />
        <origin rpy="-1.57079632679 0 0" xyz="0 0 0" />
        <parent link="panda_link1" />
        <child link="panda_link2" />
        <axis xyz="0 0 1" />
        <limit effort="87" lower="-1.7628" upper="1.7628" velocity="2.1750" />
        <dynamics damping="5.0" friction="2.0" />
    </joint>
    <link name="panda_link3">
        <visual>
            <geometry>
                <mesh filename="package://franka_panda_description/meshes/visual/link3.dae" />
            </geometry>
        </visual>
        <collision>
            <geometry>
                <mesh filename="package://franka_panda_description/meshes/collision/link3.stl" />
            </geometry>
        </collision>
        <inertial>
            <origin rpy="0 0 0" xyz="2.7518e-02 3.9252e-02 -6.6502e-02" />
            <mass value="3.228604" />
            <inertia ixx="3.7242e-02" ixy="-4.7610e-03" ixz="-1.1396e-02" iyy="3.6155e-02" iyz="-1.2805e-02" izz="1.0830e-02" />
        </inertial>
    </link>
    <joint name="panda_joint3" type="revolute">
        <safety_controller k_position="100.0" k_velocity="40.0" soft_lower_limit="-2.8973" soft_upper_limit="2.8973" />
        <origin rpy="1.57079632679 0 0" xyz="0 -0.316 0" />
        <parent link="panda_link2" />
        <child link="panda_link3" />
        <axis xyz="0 0 1" />
        <limit effort="87" lower="-2.8973" upper="2.8973" velocity="2.1750" />
        <dynamics damping="5.0" friction="2.0" />
    </joint>
    <link name="panda_link4">
        <visual>
            <geometry>
                <mesh filename="package://franka_panda_description/meshes/visual/link4.dae" />
            </geometry>
        </visual>
        <collision>
            <geometry>
                <mesh filename="package://franka_panda_description/meshes/collision/link4.stl" />
            </geometry>
        </collision>
        <inertial>
            <origin rpy="0 0 0" xyz="-5.317e-02 1.04419e-01 2.7454e-02" />
            <mass value="3.587895" />
            <inertia ixx="2.5853e-02" ixy="7.7960e-03" ixz="-1.3320e-03" iyy="1.9552e-02" iyz="8.6410e-03" izz="2.8323e-02" />
        </inertial>
    </link>
    <joint name="panda_joint4" type="revolute">
        <safety_controller k_position="100.0" k_velocity="40.0" soft_lower_limit="-3.0718" soft_upper_limit="-0.0698" />
        <origin rpy="1.57079632679 0 0" xyz="0.0825 0 0" />
        <parent link="panda_link3" />
        <child link="panda_link4" />
        <axis xyz="0 0 1" />
        <limit effort="87" lower="-3.0718" upper="-0.0698" velocity="2.1750" />
        <dynamics damping="1.0" friction="0.5" />
    </joint>
    <link name="panda_link5">
        <visual>
            <geometry>
                <mesh filename="package://franka_panda_description/meshes/visual/link5.dae" />
            </geometry>
        </visual>
        <collision>
            <geometry>
                <mesh filename="package://franka_panda_description/meshes/collision/link5.stl" />
            </geometry>
        </collision>
        <inertial>
            <origin rpy="0 0 0" xyz="-1.1953e-02 4.1065e-02 -3.8437e-02" />
            <mass value="1.225946" />
            <inertia ixx="3.5549e-02" ixy="-2.1170e-03" ixz="-4.0370e-03" iyy="2.9474e-02" iyz="2.2900e-04" izz="8.6270e-03" />
        </inertial>
    </link>
    <joint name="panda_joint5" type="revolute">
        <safety_controller k_position="100.0" k_velocity="40.0" soft_lower_limit="-2.8973" soft_upper_limit="2.8973" />
        <origin rpy="-1.57079632679 0 0" xyz="-0.0825 0.384 0" />
        <parent link="panda_link4" />
        <child link="panda_link5" />
        <axis xyz="0 0 1" />
        <limit effort="12" lower="-2.8973" upper="2.8973" velocity="2.6100" />
        <dynamics damping="2.0" friction="1.0" />
    </joint>
    <link name="panda_link6">
        <visual>
            <geometry>
                <mesh filename="package://franka_panda_description/meshes/visual/link6.dae" />
            </geometry>
        </visual>
        <collision>
            <geometry>
                <mesh filename="package://franka_panda_description/meshes/collision/link6.stl" />
            </geometry>
        </collision>
        <inertial>
            <origin rpy="0 0 0" xyz="6.0149e-02 -1.4117e-02 -1.0517e-02" />
            <mass value="1.666555" />
            <inertia ixx="1.9640e-03" ixy="1.0900e-04" ixz="-1.1580e-03" iyy="4.3540e-03" iyz="3.4100e-04" izz="5.4330e-03" />
        </inertial>
    </link>
    <joint name="panda_joint6" type="revolute">
        <safety_controller k_position="100.0" k_velocity="40.0" soft_lower_limit="-0.0175" soft_upper_limit="3.7525" />
        <origin rpy="1.57079632679 0 0" xyz="0 0 0" />
        <parent link="panda_link5" />
        <child link="panda_link6" />
        <axis xyz="0 0 1" />
        <limit effort="12" lower="-0.0175" upper="3.7525" velocity="2.6100" />
        <dynamics damping="1.0" friction="0.5" />
    </joint>
    <link name="panda_link7">
        <visual>
            <geometry>
                <mesh filename="package://franka_panda_description/meshes/visual/link7.dae" />
            </geometry>
            <!-- <material name="panda_gray"/> -->
        </visual>
        <collision>
            <geometry>
                <mesh filename="package://franka_panda_description/meshes/collision/link7.stl" />
            </geometry>
        </collision>
        <inertial>
            <origin rpy="0 0 0" xyz="1.0517e-02 -4.252e-03 6.1597e-02" />
            <mass value="7.35522e-01" />
            <inertia ixx="1.2516e-02" ixy="-4.2800e-04" ixz="-1.1960e-03" iyy="1.0027e-02" iyz="-7.4100e-04" izz="4.8150e-03" />
        </inertial>
    </link>
    <joint name="panda_joint7" type="revolute">
        <safety_controller k_position="100.0" k_velocity="40.0" soft_lower_limit="-2.8973" soft_upper_limit="2.8973" />
        <origin rpy="1.57079632679 0 0" xyz="0.088 0 0" />
        <parent link="panda_link6" />
        <child link="panda_link7" />
        <axis xyz="0 0 1" />
        <limit effort="12" lower="-2.8973" upper="2.8973" velocity="2.6100" />
        <!-- <dynamics damping="1.0" friction="0.5" /> -->
    </joint>
    <link name="panda_link8">
        <inertial>
            <origin rpy="0 0 0" xyz="0 0 0" />
            <mass value="0.0" />
            <inertia ixx="0.001" ixy="0.0" ixz="0.0" iyy="0.001" iyz="0.0" izz="0.001" />
        </inertial>
    </link>
    <joint name="panda_joint8" type="fixed">
        <origin rpy="0 0 0" xyz="0 0 0.107" />
        <parent link="panda_link7" />
        <child link="panda_link8" />
        <axis xyz="0 0 0" />
    </joint>
    <joint name="panda_hand_joint" type="fixed">
        <parent link="panda_link8" />
        <child link="rh_p12_rn_base" />
        <origin xyz="0 0 0" rpy="0 0 0" />
    </joint>
    <!-- <joint name="world_fixed" type="fixed">
    <origin xyz="0 0 0" rpy="0 0 0"/>
    <parent link="world"/>
    <child link="rh_p12_rn_base"/>
  </joint> -->
    <!-- base -->
    <link name="rh_p12_rn_base">
        <collision>
            <origin xyz="0 0 0" rpy="0 0 0" />
            <geometry>
                <mesh filename="package://rh_p12_rn_description/meshes/base.stl" scale="0.001 0.001 0.001" />
            </geometry>
        </collision>
        <visual>
            <origin xyz="0 0 0" rpy="0 0 0" />
            <geometry>
                <mesh filename="package://rh_p12_rn_description/meshes/base.stl" scale="0.001 0.001 0.001" />
            </geometry>
            <material name="grey" />
        </visual>
        <inertial>
            <origin xyz="0.000 0.000 0.032" rpy="0 0 0" />
            <mass value="0.236" />
            <!--<inertia ixx="0.00017" ixy="0.0" ixz="0.0" iyy="0.00011" iyz="0.0" izz="0.00017" />-->
            <inertia ixx="1.0" ixy="0.0" ixz="0.0" iyy="1.0" iyz="0.0" izz="1.0" />
        </inertial>
    </link>
    <!-- Joint -->
    <joint name="rh_p12_rn" type="revolute">
    <parent link="rh_p12_rn_base"/>
    <child link="rh_p12_rn_r1"/>
    <origin xyz="0.0 0.008 0.048" rpy="0 0 0"/>
    <axis xyz="1 0 0"/>
    <limit velocity="2.5" effort="100" lower="0.0" upper="1.1" />
    <dynamics damping="0.7"/>
  </joint>


  <!-- rh_p12_rn_r1 -->
  <link name="rh_p12_rn_r1">
    <collision>
      <origin xyz="0 0 0" rpy="0 0 0"/>
      <geometry>
        <mesh filename="package://rh_p12_rn_description/meshes/r1.stl" scale="0.001 0.001 0.001"/>
      </geometry>
    </collision>

    <visual>
      <origin xyz="0 0 0" rpy="0 0 0"/>
      <geometry>
        <mesh filename="package://rh_p12_rn_description/meshes/r1.stl" scale="0.001 0.001 0.001"/>
      </geometry>
      <material name="grey"/>
    </visual>

    <inertial>
      <origin xyz="0.000 0.034 0.004" rpy="0 0 0"/>
      <mass value="0.068"/>
      <!--<inertia ixx="0.00004" ixy="0.0" ixz="0.0" iyy="0.00002" iyz="-0.00001" izz="0.00002" />-->
      <inertia ixx="1.0" ixy="0.0" ixz="0.0" iyy="1.0" iyz="0.0" izz="1.0" />
    </inertial>
  </link>

  <!-- Right Joint 2 -->
  <joint name="rh_r2" type="fixed">
    <parent link="rh_p12_rn_r1"/>
    <child link="rh_p12_rn_r2"/>
    <origin xyz="0.0 0.0493634 0.0285" rpy="0 0 0"/>
    <!-- <axis xyz="-1 0 0"/>
    <limit velocity="6.5" effort="1000" lower="0.0" upper="1.0" />
    <dynamics damping="0.7"/> -->
  </joint>

  <!-- rh_p12_rn_r2 -->
  <link name="rh_p12_rn_r2">
    <collision>
      <origin xyz="0 0 0" rpy="0 0 0"/>
      <geometry>
        <mesh filename="package://rh_p12_rn_description/meshes/r2.stl" scale="0.001 0.001 0.001"/>
      </geometry>
    </collision>

    <visual>
      <origin xyz="0 0 0" rpy="0 0 0"/>
      <geometry>
        <mesh filename="package://rh_p12_rn_description/meshes/r2.stl" scale="0.001 0.001 0.001"/>
      </geometry>
      <material name="grey"/>
    </visual>

    <inertial>
      <origin xyz="0.000 0.006 0.011" rpy="0 0 0"/>
      <mass value="0.022"/>
      <!--<inertia ixx="0.0" ixy="0.0" ixz="0.0" iyy="0.00001" iyz="0.0" izz="0.0" />-->
      <inertia ixx="1.0" ixy="0.0" ixz="0.0" iyy="1.0" iyz="0.0" izz="1.0" />
    </inertial>
  </link>

  <!-- Left Joint 1 -->
  <joint name="rh_l1" type="revolute">
    <parent link="rh_p12_rn_base"/>
    <child link="rh_p12_rn_l1"/>
    <origin xyz="0.0 -0.008 0.048" rpy="0 0 0"/>
    <axis xyz="-1 0 0"/>
    <limit velocity="2.5" effort="100" lower="0.0" upper="1.1" />
    <dynamics damping="0.7"/>
  </joint>


    <!-- x = front  y =right  z = up -->
    <!-- 0.03 0 -0.32 -->
  <joint name="lidar_front_joint" type="fixed">
    <axis xyz="0 0 0" />
    <origin rpy="0 0 0" xyz="0 0 -0.075" />
    <parent link="l_shaped_second_link"/>
    <child link="base_lidar_front"/>
</joint>

<link name="base_lidar_front">
    <collision>
      <origin xyz="0 0 0" rpy="0 0 0"/>
      <geometry>
        <box size="0.01 0.01 0.01"/>
      </geometry>
    </collision>    <visual>
      <origin xyz="0 0 0" rpy="0 0 0"/>
      <geometry>
        <box size="0.01 0.01 0.01"/>
      </geometry>
    </visual>    <inertial>
      <mass value="1e-5" />
      <origin xyz="0 0 0" rpy="0 0 0"/>
      <inertia ixx="1e-6" ixy="0" ixz="0" iyy="1e-6" iyz="0"      izz="1e-6" />
    </inertial>
</link>

<joint name="l_shaped_first" type="fixed">
    <axis xyz="0 0 0" />
    <!-- x = front  y =right  z = up -->
    <origin rpy="0 0 0" xyz="0.08 0 -0.18" />
    <parent link="panda_link1"/>
    <child link="l_shaped_first_link"/>
</joint>

<link name="l_shaped_first_link">
    <collision>
    <!-- 0.04 0.037 -0.11 -->
      <origin xyz="0 0 0" rpy="0 0 0"/>
      <geometry>
        <box size="0.02 0.01 0.01"/>
      </geometry>
    </collision>    <visual>
      <origin xyz="0 0 0" rpy="0 0 0"/>
      <geometry>
        <box size="0.2 0.01 0.01"/>
      </geometry>
    </visual>    <inertial>
      <mass value="1e-5" />
      <origin xyz="0 0 0" rpy="0 0 0"/>
      <inertia ixx="1e-6" ixy="0" ixz="0" iyy="1e-6" iyz="0"      izz="1e-6" />
    </inertial>
</link>

<joint name="l_shaped_second" type="fixed">
    <axis xyz="0 0 0" />
    <!-- x = front  y =right  z = up -->
    <!-- <origin rpy="0 0 0" xyz="-0.15 0 0.02" /> -->

    <origin rpy="0 0 0" xyz="0.095 0 -0.07" />
    <parent link="l_shaped_first_link"/>
    <child link="l_shaped_second_link"/>
</joint>

<link name="l_shaped_second_link">
    <collision>
    <!-- 0.04 0.037 -0.11 -->
      <origin xyz="0 0 0" rpy="0 0 0"/>
      <geometry>
        <box size="0.01 0.01 0.02"/>
      </geometry>
    </collision>    <visual>
      <origin xyz="0 0 0" rpy="0 0 0"/>
      <geometry>
        <box size="0.01 0.01 0.15"/>
      </geometry>
    </visual>    <inertial>
      <mass value="1e-5" />
      <origin xyz="0 0 0" rpy="0 0 0"/>
      <inertia ixx="1e-6" ixy="0" ixz="0" iyy="1e-6" iyz="0"      izz="1e-6" />
    </inertial>
</link>



  <link name="depth_camera_link">
      <visual>
          <geometry>
              <box size="0.010 0.03 0.03"/>
          </geometry>
          <material name="red"/>
      </visual>
  </link>
 <joint name="depth_camera_joint" type="fixed">
        <parent link="panda_link0"/>
        <child link="depth_camera_link"/>
        <origin xyz="3 0 1" rpy="0 1.5708 0"/>
    </joint>

    <joint name="camera_optical_joint" type="fixed">
      <parent link="depth_camera_link"/>
      <child link="camera_link_optical"/>
      <origin xyz="3 0 1" rpy="0 1.5708 0"/>
    </joint>

    <link name="camera_link_optical"></link>


    




<!-- <link name="velodyne_link">
    <visual>
      <geometry>
        <cylinder length="0.1" radius="0.05"/>
      </geometry>
      
    </visual>
    <collision>
      <geometry>
        <cylinder length="0.1" radius="0.05"/>
      </geometry>
    </collision>
  </link>
  <joint name="velodyne_joint" type="fixed">
    <parent link="panda_link0"/>
    <child link="velodyne_link"/>
    <origin xyz="3 0 0.05" rpy="0 0 0"/>
  </joint> -->

    


  <!-- rh_p12_rn_l1 -->
  <link name="rh_p12_rn_l1">
    <collision>
      <origin xyz="0 0 0" rpy="0 0 0"/>
      <geometry>
        <mesh filename="package://rh_p12_rn_description/meshes/l1.stl" scale="0.001 0.001 0.001"/>
      </geometry>
    </collision>

    <visual>
      <origin xyz="0 0 0" rpy="0 0 0"/>
      <geometry>
        <mesh filename="package://rh_p12_rn_description/meshes/l1.stl" scale="0.001 0.001 0.001"/>
      </geometry>
      <material name="grey"/>
    </visual>

    <inertial>
      <origin xyz="0.000 -0.034 0.004" rpy="0 0 0"/>
      <mass value="0.068"/>
      <!--<inertia ixx="0.00004" ixy="0.0" ixz="0.0" iyy="0.00002" iyz="0.00001" izz="0.00002" />-->
      <inertia ixx="1.0" ixy="0.0" ixz="0.0" iyy="1.0" iyz="0.0" izz="1.0" />
    </inertial>
  </link>

  <!-- Left Joint 2 -->
  <joint name="rh_l2" type="fixed">
    <parent link="rh_p12_rn_l1"/>
    <child link="rh_p12_rn_l2"/>
    <origin xyz="0.0 -0.0493634 0.0285" rpy="0 0 0"/>
    <!-- <axis xyz="1 0 0"/>
    <limit velocity="6.5" effort="1000" lower="0.0" upper="1.0" />
    <dynamics damping="0.7"/> -->
  </joint>

    <!-- <link name="lidar_link">
    <visual>
      <geometry>
        <cylinder length="0.1" radius="0.05"/>
      </geometry>
      <material name="grey">
        <color rgba="0.5 0.5 0.5 1"/>
      </material>
    </visual>
    <collision>
      <geometry>
        <cylinder length="0.1" radius="0.05"/>
      </geometry>
    </collision>
    <inertial>
      <mass value="0.1"/>
      <inertia ixx="0.0001" ixy="0.0" ixz="0.0" iyy="0.0001" iyz="0.0" izz="0.0001"/>
    </inertial>
  </link>

  <joint name="lidar_joint" type="fixed">
    <parent link="panda_link0"/>
    <child link="lidar_link"/>
    <origin xyz="2 0 0.035" rpy="0 0 0"/>
  </joint> -->

  <!-- rh_p12_rn_l2 -->
  <link name="rh_p12_rn_l2">
    <collision>
      <origin xyz="0 0 0" rpy="0 0 0"/>
      <geometry>
        <mesh filename="package://rh_p12_rn_description/meshes/l2.stl" scale="0.001 0.001 0.001"/>
      </geometry>
    </collision>

    <visual>
      <origin xyz="0 0 0" rpy="0 0 0"/>
      <geometry>
        <mesh filename="package://rh_p12_rn_description/meshes/l2.stl" scale="0.001 0.001 0.001"/>
      </geometry>
      <material name="grey"/>
    </visual>

    <inertial>
      <origin xyz="0.000 -0.006 0.011" rpy="0 0 0"/>
      <mass value="0.022"/>
      <!--<inertia ixx="0.0" ixy="0.0" ixz="0.0" iyy="0.00001" iyz="0.0" izz="0.0" />-->
      <inertia ixx="1.0" ixy="0.0" ixz="0.0" iyy="1.0" iyz="0.0" izz="1.0" />
    </inertial>
  </link>

    <transmission name="trans_panda_joint1">
        <type>transmission_interface/SimpleTransmission</type>
        <joint name="panda_joint1">
            <hardwareInterface>hardware_interface/PositionJointInterface</hardwareInterface>
        </joint>
        <actuator name="panda_joint1_motor">
            <hardwareInterface>hardware_interface/PositionJointInterface</hardwareInterface>
            <mechanicalReduction>1</mechanicalReduction>
        </actuator>
    </transmission>
    <transmission name="trans_panda_joint2">
        <type>transmission_interface/SimpleTransmission</type>
        <joint name="panda_joint2">
            <hardwareInterface>hardware_interface/PositionJointInterface</hardwareInterface>
        </joint>
        <actuator name="panda_joint2_motor">
            <hardwareInterface>hardware_interface/PositionJointInterface</hardwareInterface>
            <mechanicalReduction>1</mechanicalReduction>
        </actuator>
    </transmission>
    <transmission name="trans_panda_joint3">
        <type>transmission_interface/SimpleTransmission</type>
        <joint name="panda_joint3">
            <hardwareInterface>hardware_interface/PositionJointInterface</hardwareInterface>
        </joint>
        <actuator name="panda_joint3_motor">
            <hardwareInterface>hardware_interface/PositionJointInterface</hardwareInterface>
            <mechanicalReduction>1</mechanicalReduction>
        </actuator>
    </transmission>
    <transmission name="trans_panda_joint4">
        <type>transmission_interface/SimpleTransmission</type>
        <joint name="panda_joint4">
            <hardwareInterface>hardware_interface/PositionJointInterface</hardwareInterface>
        </joint>
        <actuator name="panda_joint4_motor">
            <hardwareInterface>hardware_interface/PositionJointInterface</hardwareInterface>
            <mechanicalReduction>1</mechanicalReduction>
        </actuator>
    </transmission>
    <transmission name="trans_panda_joint5">
        <type>transmission_interface/SimpleTransmission</type>
        <joint name="panda_joint5">
            <hardwareInterface>hardware_interface/PositionJointInterface</hardwareInterface>
        </joint>
        <actuator name="panda_joint5_motor">
            <hardwareInterface>hardware_interface/PositionJointInterface</hardwareInterface>
            <mechanicalReduction>1</mechanicalReduction>
        </actuator>
    </transmission>
    <transmission name="trans_panda_joint6">
        <type>transmission_interface/SimpleTransmission</type>
        <joint name="panda_joint6">
            <hardwareInterface>hardware_interface/PositionJointInterface</hardwareInterface>
        </joint>
        <actuator name="panda_joint6_motor">
            <hardwareInterface>hardware_interface/PositionJointInterface</hardwareInterface>
            <mechanicalReduction>1</mechanicalReduction>
        </actuator>
    </transmission>
    <transmission name="trans_panda_joint7">
        <type>transmission_interface/SimpleTransmission</type>
        <joint name="panda_joint7">
            <hardwareInterface>hardware_interface/PositionJointInterface</hardwareInterface>
        </joint>
        <actuator name="panda_joint7_motor">
            <hardwareInterface>hardware_interface/PositionJointInterface</hardwareInterface>
            <mechanicalReduction>1</mechanicalReduction>
        </actuator>
    </transmission>
    <transmission name="trans_rh_p12_rn">
        <type>transmission_interface/SimpleTransmission</type>
        <joint name="rh_p12_rn">
            <hardwareInterface>hardware_interface/EffortJointInterface</hardwareInterface>
        </joint>
        <actuator name="rh_p12_rn_motor">
            <hardwareInterface>hardware_interface/EffortJointInterface</hardwareInterface>
            <mechanicalReduction>1</mechanicalReduction>
        </actuator>
    </transmission>
    <transmission name="trans_rh_l1">
        <type>transmission_interface/SimpleTransmission</type>
        <joint name="rh_l1">
            <hardwareInterface>hardware_interface/EffortJointInterface</hardwareInterface>
        </joint>
        <actuator name="rh_l1_motor">
            <hardwareInterface>hardware_interface/EffortJointInterface</hardwareInterface>
            <mechanicalReduction>1</mechanicalReduction>
        </actuator>
    </transmission>
    <gazebo>
        <plugin name="gazebo_ros_control" filename="libgazebo_ros_control.so">
            <robotNamespace>/</robotNamespace>
        </plugin>
    </gazebo>
<gazebo>
   <plugin name="gazebo_grasp_fix" filename="libgazebo_grasp_fix.so">
        <arm>
           <arm_name>panda</arm_name>
           <palm_link>panda_link7</palm_link>
           <gripper_link>rh_p12_rn_l1</gripper_link>
           <gripper_link>rh_p12_rn_r1</gripper_link>
           <!-- <gripper_link> ... </gripper_link> -->
        </arm>
       <forces_angle_tolerance>100</forces_angle_tolerance>
       <update_rate>4</update_rate>
       <grip_count_threshold>4</grip_count_threshold>
       <max_grip_count>8</max_grip_count>
       <release_tolerance>0.005</release_tolerance>
       <disable_collisions_on_attach>false</disable_collisions_on_attach>
       <contact_topic>__default_topic__</contact_topic>
    </plugin>
</gazebo>

<!-- <gazebo reference="base_ir_front">        
   <sensor type="ray" name="laser">
      <pose>0 0 0 0 0 0</pose>
      <visualize>true</visualize>
      <update_rate>50</update_rate>
      <ray>
         <scan>
            <horizontal>
               <samples>10</samples>
               <resolution>1</resolution> 
               <min_angle>-0.14835</min_angle>
               <max_angle>0.14835</max_angle>
            </horizontal>
            <vertical>
               <samples>10</samples>
               <resolution>1</resolution> 
               <min_angle>-0.1</min_angle>
               <max_angle>0.1</max_angle> 
            </vertical>
         </scan>
         <range>
            <min>0.01</min>
            <max>2</max>
            <resolution>0.02</resolution>
         </range>
      </ray>
      <plugin filename="libgazebo_ros_laser.so" name="gazebo_ros_laser">
         <alwaysOn>true</alwaysOn>
        <updateRate>10.0</updateRate>
        <topicName>/lidar_points</topicName>
        <frameName>base_ir_front</frameName>
        <min_angle>-1.5708</min_angle>
        <max_angle>1.5708</max_angle>
        <gaussianNoise>0.01</gaussianNoise>
        <laserRetro>0.0</laserRetro>
        <rangeMin>0.5</rangeMin>
        <rangeMax>10.0</rangeMax>
        <resolution>0.01</resolution>
        <samples>640</samples>
    </plugin>
   </sensor>  
   </gazebo> -->

    <!-- <gazebo>
    <plugin name="ros_ray_sensor_controller" filename="libgazebo_ros_laser.so">
      <alwaysOn>true</alwaysOn>
      <updateRate>10.0</updateRate>
      <topicName>/lidar_points</topicName>
      <frameName>lidar_link</frameName>
      <min_angle>-1.5708</min_angle>
      <max_angle>1.5708</max_angle>
      <gaussianNoise>0.01</gaussianNoise>
      <laserRetro>0.0</laserRetro>
      <rangeMin>0.5</rangeMin>
      <rangeMax>10.0</rangeMax>
      <resolution>0.01</resolution>
      <samples>640</samples>
    </plugin>
  </gazebo> -->

  <!-- <gazebo>
    <plugin name="gazebo_ros_velodyne" filename="libgazebo_ros_velodyne.so">
      <robotNamespace>/</robotNamespace>
      <topicName>/velodyne_points</topicName>
      <frameName>velodyne</frameName>
      <min_range>0.4</min_range>
      <max_range>30.0</max_range>
      <resolution>0.02</resolution>
      <min_intensity>0.0</min_intensity>
      <gaussianNoise>0.01</gaussianNoise>
      <update_rate>20.0</update_rate>
    </plugin>
  </gazebo> -->

  <gazebo reference="base_lidar_front">
    <sensor type="ray" name="lidar_sensor">
      <pose>0 0 0 0 0 0</pose>
      <visualize>true</visualize>
      <update_rate>10</update_rate>
      <ray>
        <scan>
          <horizontal>
            <samples>512</samples>
            <resolution>1</resolution>
            <!-- <min_angle>-0.785398</min_angle>
            <max_angle>0.785398</max_angle> -->
            <min_angle>-0.785398</min_angle>
            <max_angle>0.785398</max_angle>
          </horizontal>
        </scan>
        <range>
          <min>0.1</min>
          <max>10</max>
          <resolution>0.01</resolution>
        </range>
      </ray>
      <plugin name="lidar" filename="libgazebo_ros_laser.so">
        <alwaysOn>true</alwaysOn>
        <topicName>lidar/scan</topicName>
        <frameName>velodyne_link</frameName>
      </plugin>
    </sensor>
  </gazebo>

  <gazebo reference="depth_camera_link">
  <sensor type="depth" name="depth_camera">
    <pose>0 0 0 0 0 0</pose>
    <update_rate>30</update_rate>
    <camera>
      <horizontal_fov>1.047</horizontal_fov>
      <image>
        <width>640</width>
        <height>480</height>
        <format>R8G8B8</format>
      </image>
      <clip>
        <near>0.1</near>
        <far>10.0</far>
      </clip>
    </camera>
    <plugin name="camera_controller" filename="libgazebo_ros_openni_kinect.so">
      <alwaysOn>true</alwaysOn>
      <updateRate>30</updateRate>
      <cameraName>depth_camera</cameraName>
      <imageTopicName>depth/image_raw</imageTopicName>
      <cameraInfoTopicName>depth/camera_info</cameraInfoTopicName>
      <pointCloudTopicName>/cloud_stitched</pointCloudTopicName>
      <frameName>depth_camera_link</frameName>
    </plugin>
  </sensor>
</gazebo>

 <gazebo reference="rh_p12_rn">
 <provideFeedback>true</provideFeedback>
 </gazebo>
 <!-- The ft_sensor plugin -->
 <gazebo>
 <plugin name="ft_sensor" filename="libgazebo_ros_ft_sensor.so">
 <updateRate>100.0</updateRate>
 <topicName>right_force_sensor</topicName>
 <jointName>rh_p12_rn</jointName>
 </plugin>
 </gazebo>

  <gazebo reference="rh_l1">
 <provideFeedback>true</provideFeedback>
 </gazebo>
 <!-- The ft_sensor plugin -->
 <gazebo>
 <plugin name="ft_sensor" filename="libgazebo_ros_ft_sensor.so">
 <updateRate>100.0</updateRate>
 <topicName>left_force_sensor</topicName>
 <jointName>rh_l1</jointName>
 </plugin>
 </gazebo>


</robot>

